<?xml version="1.0"?>
<robot name="ic120" xmlns:xacro="http://ros.org/wiki/xacro" >
  <xacro:property name="PI" value="3.1415926535" />
  <xacro:property name="temp_mass" value="1" />
  <xacro:property name="base_mass" value="1" />
  <xacro:property name="model_offset_x" value="3.1" />
  <xacro:property name="model_offset_y" value="-1.5" />
  <!-- <xacro:property name="model_offset_x" value="-1.5" />
  <xacro:property name="model_offset_y" value="-3.1" /> -->

  <xacro:include filename="$(find ic120_description)/urdf/ic120.xacro"/>

  <xacro:macro name="wheel_macro" params="parent prefix xyz">
    <joint name="${prefix}_joint" type="continuous">
      <origin xyz="${xyz}" rpy="${radians(-90)} 0 0"/>
      <parent link="${parent}"/>
      <child  link="${prefix}_link"/>
      <axis xyz="0 0 1" />
    </joint>
    <transmission name="${prefix}_trans" type="SimpleTransmission">
      <type>transmission_interface/SimpleTransmission</type>
        <actuator name="${prefix}_motor">
          <mechanicalReduction>1</mechanicalReduction>
        </actuator>
      <joint name="${prefix}_joint">
        <hardwareInterface>hardware_interface/VelocityJointInterface</hardwareInterface>
      </joint>
    </transmission>
    <link name="${prefix}_link">
      <inertial>
        <origin xyz="0 0 0" rpy="0 0 0"/>
        <mass value="1"/>
        <inertia ixx="1" ixy="0.0" ixz="0.0" iyy="1" iyz="0.0" izz="1"/>
      </inertial>
      <collision>
        <geometry>
          <cylinder radius="0.5" length="0.3" />
        </geometry>
      </collision>
    </link>
    <gazebo reference="${prefix}_link">
      <!--material>Gazebo/Red</material-->
      <mu1 value="10" />
      <mu2 value="10" />
      <kp value="1000000.0" />
      <kd value="1000" />
    </gazebo>
  </xacro:macro> 

  <xacro:macro name="fake_wheel_macro" params="parent prefix xyz">
    <joint name="${prefix}_joint" type="continuous">
      <origin xyz="${xyz}" rpy="${radians(-90)} 0 0"/>
      <parent link="${parent}"/>
      <child  link="${prefix}_link"/>
      <axis xyz="0 0 1" />
    </joint>
    <link name="${prefix}_link">
      <inertial>
        <origin xyz="0 0 0" rpy="0 0 0"/>
        <mass value="1"/>
        <inertia ixx="1" ixy="0.0" ixz="0.0" iyy="1" iyz="0.0" izz="1"/>
      </inertial>
      <collision>
        <geometry>
          <cylinder radius="0.5" length="0.3" />
        </geometry>
      </collision>
    </link>
    <gazebo reference="${prefix}_link">
      <!--material>Gazebo/Red</material-->
      <mu1 value="0" />
      <mu2 value="0" />
    </gazebo>
  </xacro:macro> 

  <!--Track(Multi Wheel) Definition-->
  <xacro:wheel_macro prefix="left_middle_wheel"  parent="base_link" xyz="0 2 0.5"/>
  <xacro:fake_wheel_macro prefix="left_front_wheel"  parent="base_link" xyz="1.5 1 0.5"/>
  <xacro:fake_wheel_macro prefix="left_rear_wheel"  parent="base_link" xyz="-1.5 1 0.5"/>

  <xacro:wheel_macro prefix="right_middle_wheel"  parent="base_link" xyz="0 -2 0.5"/>
  <xacro:fake_wheel_macro prefix="right_front_wheel"  parent="base_link" xyz="1.5 -1 0.5"/>
  <xacro:fake_wheel_macro prefix="right_rear_wheel"  parent="base_link" xyz="-1.5 -1 0.5"/>

  <gazebo>
    <plugin name="gazebo_ros_control" filename="libgazebo_ros_control.so"/>
  </gazebo>


</robot>